Workbook

Sheet Assumptions
A1: Income Forecaster — Chance Peare
A2: Horizon: June 2026 – May 2027 | Updated: May 29, 2026 | Pessimistic per Framework OPS standard
A4: INPUT ASSUMPTIONS
A5: Skyright W2 (monthly gross) | B5: 8000 | C5: Stable W2. Tax handled by employer withholding.
A6: Carlos retainer — June ramp | B6: 1500 | C6: Half month / partial scope.
A7: Carlos retainer — Jul onward | B7: 3000 | C7: Full retainer starts July.
A8: Client 3 retainer (monthly) | B8: 3000 | C8: New client assumed signed for Sep onset.
A9: Client 3 start month # | B9: 4 | C9: Month number (1=Jun26, 4=Sep26, 12=May27).
A10: Daniel + Upwork variable (monthly est) | B10: 2000 | C10: Project-based. Lumpy in reality.
A11: SCENARIO HAIRCUTS
A12: Downside: Carlos churn month (1–12, 0=never) | B12: 10 | C12: Default month 10 = pessimistic churn.
A13: Downside: Client 3 churn month (1–12, 0=never) | B13: 9 | C13: New client = highest churn risk. Default = month 9.
A14: Downside: Variable work haircut % | B14: 0.5 | C14: Discount on Daniel/Upwork.
A15: Downside: Skyright continuity | B15: 1 | C15: 1.00 = stays. Drop to model W2 loss.
A16: Upside: Variable work uplift % | B16: 0.25 | C16: Modest uplift in upside.
A18: COLOR KEY
A19: Blue text | B19: Hardcoded input — change these
A20: Black text | B20: Formula / calculation
A21: Yellow fill | B21: Key assumption — sanity-check
A24: PERSONAL / HOUSEHOLD INPUTS
A25: Sale close month # (1=Jun26, 2=Jul, 3=Aug) | B25: 2 | C25: Default Jul-26 — edit per actual close.
A26: Current PITI (until sale) | B26: 3600 | C26: Mortgage + tax + insurance.
A27: Net sale proceeds (post-costs) | B27: 95000 | C27: $615K sale − $471K mortgage − ~$48K (8% costs, pessimistic).
A28: Bridge rent (post-sale) | B28: 3200 | C28: 1-year rental during transition.
A29: Moving costs (one-time) | B29: 5000 | C29: Movers, storage, misc.
A30: Rent deposit (1st + last) | B30: 6400 | C30: 2 months rent at $3,200.
A31: Health insurance (paycheck) | B31: 400 | C31: Midpoint of $200–600 range.
A32: Auto loan payment | B32: 198 | C32: 7% APR, 5-yr, ~$10K balance.
A33: Personal loan #1 payment | B33: 334 | C33: $13K balance, 4 yrs left, ~10.5% APR (calc).
A34: Personal loan #2 payment | B34: 499 | C34: $24.5K balance, 6 yrs, 12.72% APR.
A35: CC balance (paid at sale) | B35: 16000 | C35: Eliminated month of sale.
A36: CC monthly min (until paid off) | B36: 400 | C36: ~2.5% of balance.
... A49: Starting 401(k) balance | B49: 22000 | C49: Skyright 401(k) balance today.
A51: FRAMEWORK OPS EXPENSE INPUTS
A52: Claude (monthly) | B52: 100 | C52: Per user.
A53: Railway (monthly) | B53: 20 | C53: Per user.
A54: Business phones | B54: 100 | C54: Per user.
A55: Internet allocation to business (30%) | B55: 27 | C55: 30% of $90.
A56: CPA / bookkeeping accrual | B56: 125 | C56: NOT YET INCURRED. Annual return + advisory ~$1.5K/yr. Reserve now.
A57: E&O / GL insurance (est) | B57: 75 | C57: NOT YET IN PLACE. $50–100/mo for new fractional COO.
...

Sheet Forecast
A1: 12-Month Income Forecast
A3: Source | B3: Jun-26 | C3: Jul-26 | D3: Aug-26 | E3: Sep-26 | F3: Oct-26 | G3: Nov-26 | H3: Dec-26 | I3: Jan-27 | J3: Feb-27 | K3: Mar-27 | L3: Apr-27 | M3: May-27 | N3: Total | O3: Avg/mo
A4: BASE SCENARIO
A5: Skyright W2 | B5: =Assumptions!$B$5 -> 8000 | C5: =Assumptions!$B$5 -> 8000 | D5: =Assumptions!$B$5 -> 8000 | E5: =Assumptions!$B$5 -> 8000 | F5: =Assumptions!$B$5 -> 8000 | G5: =Assumptions!$B$5 -> 8000 | H5: =Assumptions!$B$5 -> 8000 | I5: =Assumptions!$B$5 -> 8000 | ... M5: =Assumptions!$B$5 -> 8000 | N5: =SUM(B5:M5) -> 96000 | O5: =AVERAGE(B5:M5) -> 8000
A6: Carlos | B6: =Assumptions!$B$6 -> 1500 | C6: =Assumptions!$B$7 -> 3000 | D6: =Assumptions!$B$7 -> 3000 | E6: =Assumptions!$B$7 -> 3000 | F6: =Assumptions!$B$7 -> 3000 | G6: =Assumptions!$B$7 -> 3000 | H6: =Assumptions!$B$7 -> 3000 | I6: =Assumptions!$B$7 -> 3000 | J6: =Assumptions!$B$7 -> 3000 | ... M6: =Assumptions!$B$7 -> 3000 | N6: =SUM(B6:M6) -> 34500 | O6: =AVERAGE(B6:M6) -> 2875
A7: Client 3 (Sep ramp) | B7: =IF(1>=Assumptions!$B$9,Assumptions!$B$8,0) -> 0 | C7: =IF(2>=Assumptions!$B$9,Assumptions!$B$8,0) -> 0 | D7: =IF(3>=Assumptions!$B$9,Assumptions!$B$8,0) -> 0 | E7: =IF(4>=Assumptions!$B$9,Assumptions!$B$8,0) -> 3000 | F7: =IF(5>=Assumptions!$B$9,Assumptions!$B$8,0) -> 3000 | G7: =IF(6>=Assumptions!$B$9,Assumptions!$B$8,0) -> 3000 | H7: =IF(7>=Assumptions!$B$9,Assumptions!$B$8,0) -> 3000 | I7: =IF(8>=Assumptions!$B$9,Assumptions!$B$8,0) -> 3000 | J7: =IF(9>=Assumptions!$B$9,Assumptions!$B$8,0) -> 3000 | K7: =IF(10>=Assumptions!$B$9,Assumptions!$B$8,0) -> 3000 | L7: =IF(11>=Assumptions!$B$9,Assumptions!$B$8,0) -> 3000 | M7: =IF(12>=Assumptions!$B$9,Assumptions!$B$8,0) -> 3000 | N7: =SUM(B7:M7) -> 27000 | O7: =AVERAGE(B7:M7) -> 2250
A8: Daniel + Upwork (variable) | B8: =Assumptions!$B$10 -> 2000 | C8: =Assumptions!$B$10 -> 2000 | D8: =Assumptions!$B$10 -> 2000 | E8: =Assumptions!$B$10 -> 2000 | F8: =Assumptions!$B$10 -> 2000 | G8: =Assumptions!$B$10 -> 2000 | H8: =Assumptions!$B$10 -> 2000 | I8: =Assumptions!$B$10 -> 2000 | ... M8: =Assumptions!$B$10 -> 2000 | N8: =SUM(B8:M8) -> 24000 | O8: =AVERAGE(B8:M8) -> 2000
A9: Base Total | B9: =SUM(B5:B8) -> 11500 | C9: =SUM(C5:C8) -> 13000 | D9: =SUM(D5:D8) -> 13000 | E9: =SUM(E5:E8) -> 16000 | F9: =SUM(F5:F8) -> 16000 | G9: =SUM(G5:G8) -> 16000 | H9: =SUM(H5:H8) -> 16000 | I9: =SUM(I5:I8) -> 16000 | ... M9: =SUM(M5:M8) -> 16000 | N9: =SUM(B9:M9) -> 181500 | O9: =AVERAGE(B9:M9) -> 15125
A11: DOWNSIDE SCENARIO (pessimistic)
A12: Skyright W2 × continuity | B12: =Assumptions!$B$5*Assumptions!$B$15 -> 8000 | C12: =Assumptions!$B$5*Assumptions!$B$15 -> 8000 | D12: =Assumptions!$B$5*Assumptions!$B$15 -> 8000 | E12: =Assumptions!$B$5*Assumptions!$B$15 -> 8000 | F12: =Assumptions!$B$5*Assumptions!$B$15 -> 8000 | G12: =Assumptions!$B$5*Assumptions!$B$15 -> 8000 | H12: =Assumptions!$B$5*Assumptions!$B$15 -> 8000 | I12: =Assumptions!$B$5*Assumptions!$B$15 -> 8000 | ... M12: =Assumptions!$B$5*Assumptions!$B$15 -> 8000 | N12: =SUM(B12:M12) -> 96000 | O12: =AVERAGE(B12:M12) -> 8000
A13: Carlos × churn | B13: =IF(OR(Assumptions!$B$12=0,1<Assumptions!$B$12),Assumptions!$B$6,0) -> 1500 | C13: =IF(OR(Assumptions!$B$12=0,2<Assumptions!$B$12),Assumptions!$B$7,0) -> 3000 | D13: =IF(OR(Assumptions!$B$12=0,3<Assumptions!$B$12),Assumptions!$B$7,0) -> 3000 | E13: =IF(OR(Assumptions!$B$12=0,4<Assumptions!$B$12),Assumptions!$B$7,0) -> 3000 | F13: =IF(OR(Assumptions!$B$12=0,5<Assumptions!$B$12),Assumptions!$B$7,0) -> 3000 | G13: =IF(OR(Assumptions!$B$12=0,6<Assumptions!$B$12),Assumptions!$B$7,0) -> 3000 | H13: =IF(OR(Assumptions!$B$12=0,7<Assumptions!$B$12),Assumptions!$B$7,0) -> 3000 | I13: =IF(OR(Assumptions!$B$12=0,8<Assumptions!$B$12),Assumptions!$B$7,0) -> 3000 | J13: =IF(OR(Assumptions!$B$12=0,9<Assumptions!$B$12),Assumptions!$B$7,0) -> 3000 | K13: =IF(OR(Assumptions!$B$12=0,10<Assumptions!$B$12),Assumptions!$B$7,0) -> 0 | L13: =IF(OR(Assumptions!$B$12=0,11<Assumptions!$B$12),Assumptions!$B$7,0) -> 0 | M13: =IF(OR(Assumptions!$B$12=0,12<Assumptions!$B$12),Assumptions!$B$7,0) -> 0 | N13: =SUM(B13:M13) -> 25500 | O13: =AVERAGE(B13:M13) -> 2125
A14: Client 3 × churn | B14: =IF(AND(1>=Assumptions!$B$9,OR(Assumptions!$B$13=0,1<Assumptions!$B$13)),Assumptions!$B$8,0) -> 0 | C14: =IF(AND(2>=Assumptions!$B$9,OR(Assumptions!$B$13=0,2<Assumptions!$B$13)),Assumptions!$B$8,0) -> 0 | D14: =IF(AND(3>=Assumptions!$B$9,OR(Assumptions!$B$13=0,3<Assumptions!$B$13)),Assumptions!$B$8,0) -> 0 | E14: =IF(AND(4>=Assumptions!$B$9,OR(Assumptions!$B$13=0,4<Assumptions!$B$13)),Assumptions!$B$8,0) -> 3000 | F14: =IF(AND(5>=Assumptions!$B$9,OR(Assumptions!$B$13=0,5<Assumptions!$B$13)),Assumptions!$B$8,0) -> 3000 | G14: =IF(AND(6>=Assumptions!$B$9,OR(Assumptions!$B$13=0,6<Assumptions!$B$13)),Assumptions!$B$8,0) -> 3000 | H14: =IF(AND(7>=Assumptions!$B$9,OR(Assumptions!$B$13=0,7<Assumptions!$B$13)),Assumptions!$B$8,0) -> 3000 | I14: =IF(AND(8>=Assumptions!$B$9,OR(Assumptions!$B$13=0,8<Assumptions!$B$13)),Assumptions!$B$8,0) -> 3000 | J14: =IF(AND(9>=Assumptions!$B$9,OR(Assumptions!$B$13=0,9<Assumptions!$B$13)),Assumptions!$B$8,0) -> 0 | K14: =IF(AND(10>=Assumptions!$B$9,OR(Assumptions!$B$13=0,10<Assumptions!$B$13)),Assumptions!$B$8,0) -> 0 | L14: =IF(AND(11>=Assumptions!$B$9,OR(Assumptions!$B$13=0,11<Assumptions!$B$13)),Assumptions!$B$8,0) -> 0 | M14: =IF(AND(12>=Assumptions!$B$9,OR(Assumptions!$B$13=0,12<Assumptions!$B$13)),Assumptions!$B$8,0) -> 0 | N14: =SUM(B14:M14) -> 15000 | O14: =AVERAGE(B14:M14) -> 1250
A15: Daniel + Upwork × (1 − haircut) | B15: =Assumptions!$B$10*(1-Assumptions!$B$14) -> 1000 | C15: =Assumptions!$B$10*(1-Assumptions!$B$14) -> 1000 | D15: =Assumptions!$B$10*(1-Assumptions!$B$14) -> 1000 | E15: =Assumptions!$B$10*(1-Assumptions!$B$14) -> 1000 | F15: =Assumptions!$B$10*(1-Assumptions!$B$14) -> 1000 | G15: =Assumptions!$B$10*(1-Assumptions!$B$14) -> 1000 | H15: =Assumptions!$B$10*(1-Assumptions!$B$14) -> 1000 | I15: =Assumptions!$B$10*(1-Assumptions!$B$14) -> 1000 | ... M15: =Assumptions!$B$10*(1-Assumptions!$B$14) -> 1000 | N15: =SUM(B15:M15) -> 12000 | O15: =AVERAGE(B15:M15) -> 1000
A16: Downside Total | B16: =SUM(B12:B15) -> 10500 | C16: =SUM(C12:C15) -> 12000 | D16: =SUM(D12:D15) -> 12000 | E16: =SUM(E12:E15) -> 15000 | F16: =SUM(F12:F15) -> 15000 | G16: =SUM(G12:G15) -> 15000 | H16: =SUM(H12:H15) -> 15000 | I16: =SUM(I12:I15) -> 15000 | ... M16: =SUM(M12:M15) -> 9000 | N16: =SUM(B16:M16) -> 148500 | O16: =AVERAGE(B16:M16) -> 12375
A18: UPSIDE SCENARIO
A19: Skyright W2 | B19: =Assumptions!$B$5 -> 8000 | C19: =Assumptions!$B$5 -> 8000 | D19: =Assumptions!$B$5 -> 8000 | E19: =Assumptions!$B$5 -> 8000 | F19: =Assumptions!$B$5 -> 8000 | G19: =Assumptions!$B$5 -> 8000 | H19: =Assumptions!$B$5 -> 8000 | I19: =Assumptions!$B$5 -> 8000 | ... M19: =Assumptions!$B$5 -> 8000 | N19: =SUM(B19:M19) -> 96000 | O19: =AVERAGE(B19:M19) -> 8000
A20: Carlos (full) | B20: =Assumptions!$B$6 -> 1500 | C20: =Assumptions!$B$7 -> 3000 | D20: =Assumptions!$B$7 -> 3000 | E20: =Assumptions!$B$7 -> 3000 | F20: =Assumptions!$B$7 -> 3000 | G20: =Assumptions!$B$7 -> 3000 | H20: =Assumptions!$B$7 -> 3000 | I20: =Assumptions!$B$7 -> 3000 | J20: =Assumptions!$B$7 -> 3000 | ... M20: =Assumptions!$B$7 -> 3000 | N20: =SUM(B20:M20) -> 34500 | O20: =AVERAGE(B20:M20) -> 2875
A21: Client 3 (Sep ramp) | B21: =IF(1>=Assumptions!$B$9,Assumptions!$B$8,0) -> 0 | C21: =IF(2>=Assumptions!$B$9,Assumptions!$B$8,0) -> 0 | D21: =IF(3>=Assumptions!$B$9,Assumptions!$B$8,0) -> 0 | E21: =IF(4>=Assumptions!$B$9,Assumptions!$B$8,0) -> 3000 | F21: =IF(5>=Assumptions!$B$9,Assumptions!$B$8,0) -> 3000 | G21: =IF(6>=Assumptions!$B$9,Assumptions!$B$8,0) -> 3000 | H21: =IF(7>=Assumptions!$B$9,Assumptions!$B$8,0) -> 3000 | I21: =IF(8>=Assumptions!$B$9,Assumptions!$B$8,0) -> 3000 | J21: =IF(9>=Assumptions!$B$9,Assumptions!$B$8,0) -> 3000 | K21: =IF(10>=Assumptions!$B$9,Assumptions!$B$8,0) -> 3000 | L21: =IF(11>=Assumptions!$B$9,Assumptions!$B$8,0) -> 3000 | M21: =IF(12>=Assumptions!$B$9,Assumptions!$B$8,0) -> 3000 | N21: =SUM(B21:M21) -> 27000 | O21: =AVERAGE(B21:M21) -> 2250
A22: Daniel + Upwork × (1 + uplift) | B22: =Assumptions!$B$10*(1+Assumptions!$B$16) -> 2500 | C22: =Assumptions!$B$10*(1+Assumptions!$B$16) -> 2500 | D22: =Assumptions!$B$10*(1+Assumptions!$B$16) -> 2500 | E22: =Assumptions!$B$10*(1+Assumptions!$B$16) -> 2500 | F22: =Assumptions!$B$10*(1+Assumptions!$B$16) -> 2500 | G22: =Assumptions!$B$10*(1+Assumptions!$B$16) -> 2500 | H22: =Assumptions!$B$10*(1+Assumptions!$B$16) -> 2500 | I22: =Assumptions!$B$10*(1+Assumptions!$B$16) -> 2500 | ... M22: =Assumptions!$B$10*(1+Assumptions!$B$16) -> 2500 | N22: =SUM(B22:M22) -> 30000 | O22: =AVERAGE(B22:M22) -> 2500
A23: Upside Total | B23: =SUM(B19:B22) -> 12000 | C23: =SUM(C19:C22) -> 13500 | D23: =SUM(D19:D22) -> 13500 | E23: =SUM(E19:E22) -> 16500 | F23: =SUM(F19:F22) -> 16500 | G23: =SUM(G19:G22) -> 16500 | H23: =SUM(H19:H22) -> 16500 | I23: =SUM(I19:I22) -> 16500 | ... M23: =SUM(M19:M22) -> 16500 | N23: =SUM(B23:M23) -> 187500 | O23: =AVERAGE(B23:M23) -> 15625

Sheet Summary
A1: Forecast Summary
A3: Scenario | B3: 12-Mo Total | C3: Avg / Month
A4: Base | B4: =Forecast!N9 -> 181500 | C4: =Forecast!O9 -> 15125
A5: Downside (pessimistic) | B5: =Forecast!N16 -> 148500 | C5: =Forecast!O16 -> 12375
A6: Upside | B6: =Forecast!N23 -> 187500 | C6: =Forecast!O23 -> 15625
A8: Composition (Base, Year 1)
A9: Skyright W2 | B9: =Forecast!N5 -> 96000 | C9: =B9/$B$4 -> 0.52892562
A10: Carlos | B10: =Forecast!N6 -> 34500 | C10: =B10/$B$4 -> 0.19008264
A11: Client 3 | B11: =Forecast!N7 -> 27000 | C11: =B11/$B$4 -> 0.14876033
A12: Daniel + Upwork | B12: =Forecast!N8 -> 24000 | C12: =B12/$B$4 -> 0.1322314
A13: Total | B13: =SUM(B9:B12) -> 181500 | C13: =SUM(C9:C12) -> 1
A15: Key takeaways
A16: • Client 3 is the most fragile new line — a Sep close is an assumption, not a signed contract.
A17: • Skyright W2 still anchors the model. If it disappears, no combination of clients replaces it Year 1.
A18: • Downside churns Carlos at month 10 and Client 3 at month 9. Edit Assumptions B12/B13 to test.
A19: • Variable work (Daniel/Upwork) halves in downside. Set to $0 to model a true dry spell.
A20: • All numbers gross. SE tax 15.3% + income tax on ~$84.5K of 1099 income (base) lands ~$25K – $30K below gross.
A21: • Capacity check: Carlos + Client 3 = 2 active retainers. CLAUDE.md ceiling is 3 Active + 1 Embedded while still COO at Skyright.
A22: Net take-home (after tax)
A23: Scenario | B23: Annual Net | C23: Monthly Net
A24: Base | B24: =Taxes!B42 -> 159086.34 | C24: =Taxes!B43 -> 13257.195
A25: Downside | B25: =Taxes!C42 -> 136146.77 | C25: =Taxes!C43 -> 11345.564
A26: Upside | B26: =Taxes!D42 -> 163257.17 | C26: =Taxes!D43 -> 13604.764
A28: Total tax liability
A29: Scenario | B29: Total Tax | C29: Effective Rate
A30: Base | B30: =Taxes!B41 -> 22413.658 | C30: =Taxes!B44 -> 0.12349123
A31: Downside | B31: =Taxes!C41 -> 12353.229 | C31: =Taxes!C44 -> 0.083186724
A32: Upside | B32: =Taxes!D41 -> 24242.827 | C32: =Taxes!D44 -> 0.12929508
A34: Consolidated household cash flow (Base)
A35: Metric | B35: Monthly | C35: Annual
A36: After-tax income | B36: =Taxes!B43 -> 13257.195 | C36: =B36*12 -> 159086.34
A37: Personal expenses (avg) | B37: ='Personal Expenses'!O21 -> 9189.5 | C37: =B37*12 -> 110274
A38: Framework OPS OpEx (avg) | B38: ='Framework OPS P&L'!O20 -> 526.16667 | C38: =B38*12 -> 6314
A39: Net household cash flow | B39: =B36-B37-B38 -> 3541.5285 | C39: =B39*12 -> 42498.342
A41: End-of-year cash position | B41: ='Cash Roll-Forward'!M12 -> 94998.342
A45: 3-Year forecast (Framework OPS revenue net of Skyright)
A46: Metric | B46: Year 1 | C46: Year 2 | D46: Year 3
A47: Skyright W2 | B47: ='3-Year Growth'!AQ6 -> 96000 | C47: ='3-Year Growth'!AR6 -> 0 | D47: ='3-Year Growth'!AS6 -> 0
A48: Framework OPS revenue | B48: ='3-Year Growth'!AQ7 -> 98000 | C48: ='3-Year Growth'!AR7 -> 169000 | D48: ='3-Year Growth'!AS7 -> 195000
A49: Total gross income | B49: ='3-Year Growth'!AQ8 -> 194000 | C49: ='3-Year Growth'!AR8 -> 169000 | D49: ='3-Year Growth'!AS8 -> 195000
...

Sheet Taxes
A1: Tax Model — Take-Home Calculator
A2: Filing: MFJ | 4 dependents (all qualifying children <17) | State tax: 0% | Year: 2025 brackets (pessimistic vs 2026)
A4: TAX INPUTS
A5: Std deduction (MFJ 2025) | B5: 30000 | C5: IRS Rev. Proc. 2024-40.
A6: # Qualifying children (CTC $2K each) | B6: 4 | C6: Per user input.
A7: # Other dependents (ODC $500 each) | B7: 0 | C7: Per user input.
A8: State income tax rate | B8: 0 | C8: Set per home state.
A9: SE earnings multiplier (0.9235) | B9: 0.9235 | C9: IRS standard — net SE × 0.9235.
A10: SE tax rate (15.3%) | B10: 0.153 | C10: 12.4% SS + 2.9% Medicare.
A11: QBI deduction rate (20%) | B11: 0.2 | C11: Sec 199A. Phases out at high AGI — not modeled.
A13: MFJ TAX BRACKETS (2025)
A14: Bracket top | B14: Rate
A15: 23850 | B15: 0.1
A16: 96950 | B16: 0.12
A17: 206700 | B17: 0.22
A18: 394600 | B18: 0.24
A19: 501050 | B19: 0.32
A20: 751600 | B20: 0.35
A21: 10000000 | B21: 0.37
A24: SCENARIO TAX CALC
A25: Line | B25: Base | C25: Downside | D25: Upside
A26: W2 income (Skyright) | B26: =Forecast!N5 -> 96000 | C26: =Forecast!N12 -> 96000 | D26: =Forecast!N19 -> 96000
A27: 1099 income (clients + variable) | B27: =(Forecast!N6+Forecast!N7+Forecast!N8) -> 85500 | C27: =(Forecast!N13+Forecast!N14+Forecast!N15) -> 52500 | D27: =(Forecast!N20+Forecast!N21+Forecast!N22) -> 91500
A28: Gross total | B28: =B26+B27 -> 181500 | C28: =C26+C27 -> 148500 | D28: =D26+D27 -> 187500
A29: SE net earnings (× 0.9235) | B29: =B27*$B$9 -> 78959.25 | C29: =C27*$B$9 -> 48483.75 | D29: =D27*$B$9 -> 84500.25
A30: SE tax (15.3%) | B30: =B29*$B$10 -> 12080.765 | C30: =C29*$B$10 -> 7418.0138 | D30: =D29*$B$10 -> 12928.538
A31: ½ SE deductible | B31: =B30/2 -> 6040.3826 | C31: =C30/2 -> 3709.0069 | D31: =D30/2 -> 6464.2691
A32: AGI | B32: =B26+B27-B31 -> 175459.62 | C32: =C26+C27-C31 -> 144790.99 | D32: =D26+D27-D31 -> 181035.73
A33: QBI base | B33: =B27-B31 -> 79459.617 | C33: =C27-C31 -> 48790.993 | D33: =D27-D31 -> 85035.731
A34: QBI deduction (20%) | B34: =MIN(B33*$B$11,MAX(0,(B32-$B$5))*$B$11) -> 15891.923 | C34: =MIN(C33*$B$11,MAX(0,(C32-$B$5))*$B$11) -> 9758.1986 | D34: =MIN(D33*$B$11,MAX(0,(D32-$B$5))*$B$11) -> 17007.146
A35: Standard deduction (MFJ) | B35: =$B$5 -> 30000 | C35: =$B$5 -> 30000 | D35: =$B$5 -> 30000
A36: Taxable income | B36: =MAX(0,B32-B34-B35) -> 129567.69 | C36: =MAX(0,C32-C34-C35) -> 105032.79 | D36: =MAX(0,D32-D34-D35) -> 134028.58
A37: Federal income tax (pre-credit) | B37: =MIN(B36,$A$15)*$B$15+MAX(0,MIN(B36,$A$16)-$A$15)*$B$16+MAX(0,MIN(B36,$A$17)-$A$16)*$B$17+MAX(0,MIN(B36,$A$18)-$A$17)*$B$18+MAX(0,MIN(B36,$A$19)-$A$18)*$B$19+MAX(0,MIN(B36,$A$20)-$A$19)*$B$20+MAX(0,MIN(B36,$A$21)-$A$20)*$B$21 -> 18332.893 | C37: =MIN(C36,$A$15)*$B$15+MAX(0,MIN(C36,$A$16)-$A$15)*$B$16+MAX(0,MIN(C36,$A$17)-$A$16)*$B$17+MAX(0,MIN(C36,$A$18)-$A$17)*$B$18+MAX(0,MIN(C36,$A$19)-$A$18)*$B$19+MAX(0,MIN(C36,$A$20)-$A$19)*$B$20+MAX(0,MIN(C36,$A$21)-$A$20)*$B$21 -> 12935.215 | D37: =MIN(D36,$A$15)*$B$15+MAX(0,MIN(D36,$A$16)-$A$15)*$B$16+MAX(0,MIN(D36,$A$17)-$A$16)*$B$17+MAX(0,MIN(D36,$A$18)-$A$17)*$B$18+MAX(0,MIN(D36,$A$19)-$A$18)*$B$19+MAX(0,MIN(D36,$A$20)-$A$19)*$B$20+MAX(0,MIN(D36,$A$21)-$A$20)*$B$21 -> 19314.289
A38: Child Tax Credit + ODC | B38: =$B$6*2000+$B$7*500 -> 8000 | C38: =$B$6*2000+$B$7*500 -> 8000 | D38: =$B$6*2000+$B$7*500 -> 8000
A39: Federal income tax (post-credit) | B39: =MAX(0,B37-B38) -> 10332.893 | C39: =MAX(0,C37-C38) -> 4935.2148 | D39: =MAX(0,D37-D38) -> 11314.289
A40: State income tax | B40: =B36*$B$8 -> 0 | C40: =C36*$B$8 -> 0 | D40: =D36*$B$8 -> 0
A41: TOTAL TAX LIABILITY | B41: =B30+B39+B40 -> 22413.658 | C41: =C30+C39+C40 -> 12353.229 | D41: =D30+D39+D40 -> 24242.827
A42: NET TAKE-HOME (annual) | B42: =B28-B41 -> 159086.34 | C42: =C28-C41 -> 136146.77 | D42: =D28-D41 -> 163257.17
A43: NET TAKE-HOME (monthly avg) | B43: =B42/12 -> 13257.195 | C43: =C42/12 -> 11345.564 | D43: =D42/12 -> 13604.764
A44: Effective tax rate | B44: =B41/B28 -> 0.12349123 | C44: =C41/C28 -> 0.083186724 | D44: =D41/D28 -> 0.12929508
...

Sheet Personal Expenses
A1: Personal Expenses — Monthly
A2: Family of 6 | Housing transition built in | Debt payoff at sale
A4: Line | B4: Jun-26 | C4: Jul-26 | D4: Aug-26 | E4: Sep-26 | F4: Oct-26 | G4: Nov-26 | H4: Dec-26 | I4: Jan-27 | J4: Feb-27 | K4: Mar-27 | L4: Apr-27 | M4: May-27 | N4: Total | O4: Avg/mo
A5: PITI (current home) | B5: =IF(1<Assumptions!$B$25,Assumptions!$B$26,0) -> 3600 | C5: =IF(2<Assumptions!$B$25,Assumptions!$B$26,0) -> 0 | D5: =IF(3<Assumptions!$B$25,Assumptions!$B$26,0) -> 0 | E5: =IF(4<Assumptions!$B$25,Assumptions!$B$26,0) -> 0 | F5: =IF(5<Assumptions!$B$25,Assumptions!$B$26,0) -> 0 | G5: =IF(6<Assumptions!$B$25,Assumptions!$B$26,0) -> 0 | H5: =IF(7<Assumptions!$B$25,Assumptions!$B$26,0) -> 0 | I5: =IF(8<Assumptions!$B$25,Assumptions!$B$26,0) -> 0 | J5: =IF(9<Assumptions!$B$25,Assumptions!$B$26,0) -> 0 | K5: =IF(10<Assumptions!$B$25,Assumptions!$B$26,0) -> 0 | L5: =IF(11<Assumptions!$B$25,Assumptions!$B$26,0) -> 0 | M5: =IF(12<Assumptions!$B$25,Assumptions!$B$26,0) -> 0 | N5: =SUM(B5:M5) -> 3600 | O5: =AVERAGE(B5:M5) -> 300
A6: Rent (bridge) | B6: =IF(1>=Assumptions!$B$25,Assumptions!$B$28,0) -> 0 | C6: =IF(2>=Assumptions!$B$25,Assumptions!$B$28,0) -> 3200 | D6: =IF(3>=Assumptions!$B$25,Assumptions!$B$28,0) -> 3200 | E6: =IF(4>=Assumptions!$B$25,Assumptions!$B$28,0) -> 3200 | F6: =IF(5>=Assumptions!$B$25,Assumptions!$B$28,0) -> 3200 | G6: =IF(6>=Assumptions!$B$25,Assumptions!$B$28,0) -> 3200 | H6: =IF(7>=Assumptions!$B$25,Assumptions!$B$28,0) -> 3200 | I6: =IF(8>=Assumptions!$B$25,Assumptions!$B$28,0) -> 3200 | J6: =IF(9>=Assumptions!$B$25,Assumptions!$B$28,0) -> 3200 | K6: =IF(10>=Assumptions!$B$25,Assumptions!$B$28,0) -> 3200 | L6: =IF(11>=Assumptions!$B$25,Assumptions!$B$28,0) -> 3200 | M6: =IF(12>=Assumptions!$B$25,Assumptions!$B$28,0) -> 3200 | N6: =SUM(B6:M6) -> 35200 | O6: =AVERAGE(B6:M6) -> 2933.3333
A7: Moving + rent deposit (one-time) | B7: =IF(1=Assumptions!$B$25,Assumptions!$B$29+Assumptions!$B$30,0) -> 0 | C7: =IF(2=Assumptions!$B$25,Assumptions!$B$29+Assumptions!$B$30,0) -> 11400 | D7: =IF(3=Assumptions!$B$25,Assumptions!$B$29+Assumptions!$B$30,0) -> 0 | E7: =IF(4=Assumptions!$B$25,Assumptions!$B$29+Assumptions!$B$30,0) -> 0 | F7: =IF(5=Assumptions!$B$25,Assumptions!$B$29+Assumptions!$B$30,0) -> 0 | G7: =IF(6=Assumptions!$B$25,Assumptions!$B$29+Assumptions!$B$30,0) -> 0 | H7: =IF(7=Assumptions!$B$25,Assumptions!$B$29+Assumptions!$B$30,0) -> 0 | I7: =IF(8=Assumptions!$B$25,Assumptions!$B$29+Assumptions!$B$30,0) -> 0 | J7: =IF(9=Assumptions!$B$25,Assumptions!$B$29+Assumptions!$B$30,0) -> 0 | K7: =IF(10=Assumptions!$B$25,Assumptions!$B$29+Assumptions!$B$30,0) -> 0 | L7: =IF(11=Assumptions!$B$25,Assumptions!$B$29+Assumptions!$B$30,0) -> 0 | M7: =IF(12=Assumptions!$B$25,Assumptions!$B$29+Assumptions!$B$30,0) -> 0 | N7: =SUM(B7:M7) -> 11400 | O7: =AVERAGE(B7:M7) -> 950
A8: Utilities (less biz internet) | B8: =Assumptions!$B$39+Assumptions!$B$40*0.7 -> 633 | C8: =Assumptions!$B$39+Assumptions!$B$40*0.7 -> 633 | D8: =Assumptions!$B$39+Assumptions!$B$40*0.7 -> 633 | E8: =Assumptions!$B$39+Assumptions!$B$40*0.7 -> 633 | F8: =Assumptions!$B$39+Assumptions!$B$40*0.7 -> 633 | G8: =Assumptions!$B$39+Assumptions!$B$40*0.7 -> 633 | H8: =Assumptions!$B$39+Assumptions!$B$40*0.7 -> 633 | I8: =Assumptions!$B$39+Assumptions!$B$40*0.7 -> 633 | ... M8: =Assumptions!$B$39+Assumptions!$B$40*0.7 -> 633 | N8: =SUM(B8:M8) -> 7596 | O8: =AVERAGE(B8:M8) -> 633
A9: Health insurance | B9: =Assumptions!$B$31 -> 400 | C9: =Assumptions!$B$31 -> 400 | D9: =Assumptions!$B$31 -> 400 | E9: =Assumptions!$B$31 -> 400 | F9: =Assumptions!$B$31 -> 400 | G9: =Assumptions!$B$31 -> 400 | H9: =Assumptions!$B$31 -> 400 | I9: =Assumptions!$B$31 -> 400 | ... M9: =Assumptions!$B$31 -> 400 | N9: =SUM(B9:M9) -> 4800 | O9: =AVERAGE(B9:M9) -> 400
A10: Auto loan | B10: =Assumptions!$B$32 -> 198 | C10: =Assumptions!$B$32 -> 198 | D10: =Assumptions!$B$32 -> 198 | E10: =Assumptions!$B$32 -> 198 | F10: =Assumptions!$B$32 -> 198 | G10: =Assumptions!$B$32 -> 198 | H10: =Assumptions!$B$32 -> 198 | I10: =Assumptions!$B$32 -> 198 | ... M10: =Assumptions!$B$32 -> 198 | N10: =SUM(B10:M10) -> 2376 | O10: =AVERAGE(B10:M10) -> 198
A11: Personal loan #1 ($13K) | B11: =IF(OR(Assumptions!$B$37=0,1<=Assumptions!$B$37),Assumptions!$B$33,0) -> 334 | C11: =IF(OR(Assumptions!$B$37=0,2<=Assumptions!$B$37),Assumptions!$B$33,0) -> 334 | D11: =IF(OR(Assumptions!$B$37=0,3<=Assumptions!$B$37),Assumptions!$B$33,0) -> 0 | E11: =IF(OR(Assumptions!$B$37=0,4<=Assumptions!$B$37),Assumptions!$B$33,0) -> 0 | F11: =IF(OR(Assumptions!$B$37=0,5<=Assumptions!$B$37),Assumptions!$B$33,0) -> 0 | G11: =IF(OR(Assumptions!$B$37=0,6<=Assumptions!$B$37),Assumptions!$B$33,0) -> 0 | H11: =IF(OR(Assumptions!$B$37=0,7<=Assumptions!$B$37),Assumptions!$B$33,0) -> 0 | I11: =IF(OR(Assumptions!$B$37=0,8<=Assumptions!$B$37),Assumptions!$B$33,0) -> 0 | J11: =IF(OR(Assumptions!$B$37=0,9<=Assumptions!$B$37),Assumptions!$B$33,0) -> 0 | K11: =IF(OR(Assumptions!$B$37=0,10<=Assumptions!$B$37),Assumptions!$B$33,0) -> 0 | L11: =IF(OR(Assumptions!$B$37=0,11<=Assumptions!$B$37),Assumptions!$B$33,0) -> 0 | M11: =IF(OR(Assumptions!$B$37=0,12<=Assumptions!$B$37),Assumptions!$B$33,0) -> 0 | N11: =SUM(B11:M11) -> 668 | O11: =AVERAGE(B11:M11) -> 55.666667
A12: Personal loan #2 ($24.5K) | B12: =IF(OR(Assumptions!$B$38=0,1<=Assumptions!$B$38),Assumptions!$B$34,0) -> 499 | C12: =IF(OR(Assumptions!$B$38=0,2<=Assumptions!$B$38),Assumptions!$B$34,0) -> 499 | D12: =IF(OR(Assumptions!$B$38=0,3<=Assumptions!$B$38),Assumptions!$B$34,0) -> 0 | E12: =IF(OR(Assumptions!$B$38=0,4<=Assumptions!$B$38),Assumptions!$B$34,0) -> 0 | F12: =IF(OR(Assumptions!$B$38=0,5<=Assumptions!$B$38),Assumptions!$B$34,0) -> 0 | G12: =IF(OR(Assumptions!$B$38=0,6<=Assumptions!$B$38),Assumptions!$B$34,0) -> 0 | H12: =IF(OR(Assumptions!$B$38=0,7<=Assumptions!$B$38),Assumptions!$B$34,0) -> 0 | I12: =IF(OR(Assumptions!$B$38=0,8<=Assumptions!$B$38),Assumptions!$B$34,0) -> 0 | J12: =IF(OR(Assumptions!$B$38=0,9<=Assumptions!$B$38),Assumptions!$B$34,0) -> 0 | K12: =IF(OR(Assumptions!$B$38=0,10<=Assumptions!$B$38),Assumptions!$B$34,0) -> 0 | L12: =IF(OR(Assumptions!$B$38=0,11<=Assumptions!$B$38),Assumptions!$B$34,0) -> 0 | M12: =IF(OR(Assumptions!$B$38=0,12<=Assumptions!$B$38),Assumptions!$B$34,0) -> 0 | N12: =SUM(B12:M12) -> 998 | O12: =AVERAGE(B12:M12) -> 83.166667
A13: CC minimum (until sale) | B13: =IF(1<Assumptions!$B$25,Assumptions!$B$36,0) -> 400 | C13: =IF(2<Assumptions!$B$25,Assumptions!$B$36,0) -> 0 | D13: =IF(3<Assumptions!$B$25,Assumptions!$B$36,0) -> 0 | E13: =IF(4<Assumptions!$B$25,Assumptions!$B$36,0) -> 0 | F13: =IF(5<Assumptions!$B$25,Assumptions!$B$36,0) -> 0 | G13: =IF(6<Assumptions!$B$25,Assumptions!$B$36,0) -> 0 | H13: =IF(7<Assumptions!$B$25,Assumptions!$B$36,0) -> 0 | I13: =IF(8<Assumptions!$B$25,Assumptions!$B$36,0) -> 0 | J13: =IF(9<Assumptions!$B$25,Assumptions!$B$36,0) -> 0 | K13: =IF(10<Assumptions!$B$25,Assumptions!$B$36,0) -> 0 | L13: =IF(11<Assumptions!$B$25,Assumptions!$B$36,0) -> 0 | M13: =IF(12<Assumptions!$B$25,Assumptions!$B$36,0) -> 0 | N13: =SUM(B13:M13) -> 400 | O13: =AVERAGE(B13:M13) -> 33.333333
A14: Groceries | B14: =Assumptions!$B$41 -> 1200 | C14: =Assumptions!$B$41 -> 1200 | D14: =Assumptions!$B$41 -> 1200 | E14: =Assumptions!$B$41 -> 1200 | F14: =Assumptions!$B$41 -> 1200 | G14: =Assumptions!$B$41 -> 1200 | H14: =Assumptions!$B$41 -> 1200 | I14: =Assumptions!$B$41 -> 1200 | ... M14: =Assumptions!$B$41 -> 1200 | N14: =SUM(B14:M14) -> 14400 | O14: =AVERAGE(B14:M14) -> 1200
A15: Child activities | B15: =Assumptions!$B$42 -> 250 | C15: =Assumptions!$B$42 -> 250 | D15: =Assumptions!$B$42 -> 250 | E15: =Assumptions!$B$42 -> 250 | F15: =Assumptions!$B$42 -> 250 | G15: =Assumptions!$B$42 -> 250 | H15: =Assumptions!$B$42 -> 250 | I15: =Assumptions!$B$42 -> 250 | ... M15: =Assumptions!$B$42 -> 250 | N15: =SUM(B15:M15) -> 3000 | O15: =AVERAGE(B15:M15) -> 250
A16: Auto fuel/maint/insurance | B16: =Assumptions!$B$43 -> 350 | C16: =Assumptions!$B$43 -> 350 | D16: =Assumptions!$B$43 -> 350 | E16: =Assumptions!$B$43 -> 350 | F16: =Assumptions!$B$43 -> 350 | G16: =Assumptions!$B$43 -> 350 | H16: =Assumptions!$B$43 -> 350 | I16: =Assumptions!$B$43 -> 350 | ... M16: =Assumptions!$B$43 -> 350 | N16: =SUM(B16:M16) -> 4200 | O16: =AVERAGE(B16:M16) -> 350
A17: Personal subscriptions | B17: =Assumptions!$B$44 -> 100 | C17: =Assumptions!$B$44 -> 100 | D17: =Assumptions!$B$44 -> 100 | E17: =Assumptions!$B$44 -> 100 | F17: =Assumptions!$B$44 -> 100 | G17: =Assumptions!$B$44 -> 100 | H17: =Assumptions!$B$44 -> 100 | I17: =Assumptions!$B$44 -> 100 | ... M17: =Assumptions!$B$44 -> 100 | N17: =SUM(B17:M17) -> 1200 | O17: =AVERAGE(B17:M17) -> 100
A18: Discretionary | B18: =Assumptions!$B$45 -> 300 | C18: =Assumptions!$B$45 -> 300 | D18: =Assumptions!$B$45 -> 300 | E18: =Assumptions!$B$45 -> 300 | F18: =Assumptions!$B$45 -> 300 | G18: =Assumptions!$B$45 -> 300 | H18: =Assumptions!$B$45 -> 300 | I18: =Assumptions!$B$45 -> 300 | ... M18: =Assumptions!$B$45 -> 300 | N18: =SUM(B18:M18) -> 3600 | O18: =AVERAGE(B18:M18) -> 300
A19: 401(k) contribution | B19: =Assumptions!$B$46 -> 320 | C19: =Assumptions!$B$46 -> 320 | D19: =Assumptions!$B$46 -> 320 | E19: =Assumptions!$B$46 -> 320 | F19: =Assumptions!$B$46 -> 320 | G19: =Assumptions!$B$46 -> 320 | H19: =Assumptions!$B$46 -> 320 | I19: =Assumptions!$B$46 -> 320 | ... M19: =Assumptions!$B$46 -> 320 | N19: =SUM(B19:M19) -> 3840 | O19: =AVERAGE(B19:M19) -> 320
A20: Roth IRA contribution | B20: =Assumptions!$B$47 -> 1083 | C20: =Assumptions!$B$47 -> 1083 | D20: =Assumptions!$B$47 -> 1083 | E20: =Assumptions!$B$47 -> 1083 | F20: =Assumptions!$B$47 -> 1083 | G20: =Assumptions!$B$47 -> 1083 | H20: =Assumptions!$B$47 -> 1083 | I20: =Assumptions!$B$47 -> 1083 | ... M20: =Assumptions!$B$47 -> 1083 | N20: =SUM(B20:M20) -> 12996 | O20: =AVERAGE(B20:M20) -> 1083
A21: TOTAL PERSONAL OUTFLOWS | B21: =SUM(B5:B20) -> 9667 | C21: =SUM(C5:C20) -> 20267 | D21: =SUM(D5:D20) -> 8034 | E21: =SUM(E5:E20) -> 8034 | F21: =SUM(F5:F20) -> 8034 | G21: =SUM(G5:G20) -> 8034 | H21: =SUM(H5:H20) -> 8034 | I21: =SUM(I5:I20) -> 8034 | ... M21: =SUM(M5:M20) -> 8034 | N21: =SUM(B21:M21) -> 110274 | O21: =AVERAGE(B21:M21) -> 9189.5

Sheet Framework OPS P&L
A1: Framework OPS LLC — Pro Forma P&L
A2: Revenue = client/variable income. Owner pay flows to personal 1040 (no W2 from LLC).
A4: Line | B4: Jun-26 | C4: Jul-26 | D4: Aug-26 | E4: Sep-26 | F4: Oct-26 | G4: Nov-26 | H4: Dec-26 | I4: Jan-27 | J4: Feb-27 | K4: Mar-27 | L4: Apr-27 | M4: May-27 | N4: Total | O4: Avg/mo
A5: REVENUE (Base scenario)
A6: Carlos retainer | B6: =Forecast!B6 -> 1500 | C6: =Forecast!C6 -> 3000 | D6: =Forecast!D6 -> 3000 | E6: =Forecast!E6 -> 3000 | F6: =Forecast!F6 -> 3000 | G6: =Forecast!G6 -> 3000 | H6: =Forecast!H6 -> 3000 | I6: =Forecast!I6 -> 3000 | ... M6: =Forecast!M6 -> 3000 | N6: =SUM(B6:M6) -> 34500 | O6: =AVERAGE(B6:M6) -> 2875
A7: Client 3 retainer | B7: =Forecast!B7 -> 0 | C7: =Forecast!C7 -> 0 | D7: =Forecast!D7 -> 0 | E7: =Forecast!E7 -> 3000 | F7: =Forecast!F7 -> 3000 | G7: =Forecast!G7 -> 3000 | H7: =Forecast!H7 -> 3000 | I7: =Forecast!I7 -> 3000 | ... M7: =Forecast!M7 -> 3000 | N7: =SUM(B7:M7) -> 27000 | O7: =AVERAGE(B7:M7) -> 2250
A8: Daniel + Upwork variable | B8: =Forecast!B8 -> 2000 | C8: =Forecast!C8 -> 2000 | D8: =Forecast!D8 -> 2000 | E8: =Forecast!E8 -> 2000 | F8: =Forecast!F8 -> 2000 | G8: =Forecast!G8 -> 2000 | H8: =Forecast!H8 -> 2000 | I8: =Forecast!I8 -> 2000 | ... M8: =Forecast!M8 -> 2000 | N8: =SUM(B8:M8) -> 24000 | O8: =AVERAGE(B8:M8) -> 2000
A9: Total Revenue | B9: =SUM(B6:B8) -> 3500 | C9: =SUM(C6:C8) -> 5000 | D9: =SUM(D6:D8) -> 5000 | E9: =SUM(E6:E8) -> 8000 | F9: =SUM(F6:F8) -> 8000 | G9: =SUM(G6:G8) -> 8000 | H9: =SUM(H6:H8) -> 8000 | I9: =SUM(I6:I8) -> 8000 | ... M9: =SUM(M6:M8) -> 8000 | N9: =SUM(B9:M9) -> 85500 | O9: =AVERAGE(B9:M9) -> 7125
A11: OPERATING EXPENSES
A12: Claude | B12: =Assumptions!$B$52 -> 100 | C12: =Assumptions!$B$52 -> 100 | D12: =Assumptions!$B$52 -> 100 | E12: =Assumptions!$B$52 -> 100 | F12: =Assumptions!$B$52 -> 100 | G12: =Assumptions!$B$52 -> 100 | H12: =Assumptions!$B$52 -> 100 | I12: =Assumptions!$B$52 -> 100 | ... M12: =Assumptions!$B$52 -> 100 | N12: =SUM(B12:M12) -> 1200 | O12: =AVERAGE(B12:M12) -> 100
A13: Railway | B13: =Assumptions!$B$53 -> 20 | C13: =Assumptions!$B$53 -> 20 | D13: =Assumptions!$B$53 -> 20 | E13: =Assumptions!$B$53 -> 20 | F13: =Assumptions!$B$53 -> 20 | G13: =Assumptions!$B$53 -> 20 | H13: =Assumptions!$B$53 -> 20 | I13: =Assumptions!$B$53 -> 20 | ... M13: =Assumptions!$B$53 -> 20 | N13: =SUM(B13:M13) -> 240 | O13: =AVERAGE(B13:M13) -> 20
A14: Business phones | B14: =Assumptions!$B$54 -> 100 | C14: =Assumptions!$B$54 -> 100 | D14: =Assumptions!$B$54 -> 100 | E14: =Assumptions!$B$54 -> 100 | F14: =Assumptions!$B$54 -> 100 | G14: =Assumptions!$B$54 -> 100 | H14: =Assumptions!$B$54 -> 100 | I14: =Assumptions!$B$54 -> 100 | ... M14: =Assumptions!$B$54 -> 100 | N14: =SUM(B14:M14) -> 1200 | O14: =AVERAGE(B14:M14) -> 100
A15: Internet (biz allocation) | B15: =Assumptions!$B$55 -> 27 | C15: =Assumptions!$B$55 -> 27 | D15: =Assumptions!$B$55 -> 27 | E15: =Assumptions!$B$55 -> 27 | F15: =Assumptions!$B$55 -> 27 | G15: =Assumptions!$B$55 -> 27 | H15: =Assumptions!$B$55 -> 27 | I15: =Assumptions!$B$55 -> 27 | ... M15: =Assumptions!$B$55 -> 27 | N15: =SUM(B15:M15) -> 324 | O15: =AVERAGE(B15:M15) -> 27
A16: CPA / bookkeeping (accrual) | B16: =Assumptions!$B$56 -> 125 | C16: =Assumptions!$B$56 -> 125 | D16: =Assumptions!$B$56 -> 125 | E16: =Assumptions!$B$56 -> 125 | F16: =Assumptions!$B$56 -> 125 | G16: =Assumptions!$B$56 -> 125 | H16: =Assumptions!$B$56 -> 125 | I16: =Assumptions!$B$56 -> 125 | ... M16: =Assumptions!$B$56 -> 125 | N16: =SUM(B16:M16) -> 1500 | O16: =AVERAGE(B16:M16) -> 125
A17: E&O / GL insurance (recommended) | B17: =Assumptions!$B$57 -> 75 | C17: =Assumptions!$B$57 -> 75 | D17: =Assumptions!$B$57 -> 75 | E17: =Assumptions!$B$57 -> 75 | F17: =Assumptions!$B$57 -> 75 | G17: =Assumptions!$B$57 -> 75 | H17: =Assumptions!$B$57 -> 75 | I17: =Assumptions!$B$57 -> 75 | ... M17: =Assumptions!$B$57 -> 75 | N17: =SUM(B17:M17) -> 900 | O17: =AVERAGE(B17:M17) -> 75
A18: Additional software reserve | B18: =Assumptions!$B$58 -> 50 | C18: =Assumptions!$B$58 -> 50 | D18: =Assumptions!$B$58 -> 50 | E18: =Assumptions!$B$58 -> 50 | F18: =Assumptions!$B$58 -> 50 | G18: =Assumptions!$B$58 -> 50 | H18: =Assumptions!$B$58 -> 50 | I18: =Assumptions!$B$58 -> 50 | ... M18: =Assumptions!$B$58 -> 50 | N18: =SUM(B18:M18) -> 600 | O18: =AVERAGE(B18:M18) -> 50
A19: LLC + agent (accrual for next renewal) | B19: =Assumptions!$B$59/12 -> 29.166667 | C19: =Assumptions!$B$59/12 -> 29.166667 | D19: =Assumptions!$B$59/12 -> 29.166667 | E19: =Assumptions!$B$59/12 -> 29.166667 | F19: =Assumptions!$B$59/12 -> 29.166667 | G19: =Assumptions!$B$59/12 -> 29.166667 | H19: =Assumptions!$B$59/12 -> 29.166667 | I19: =Assumptions!$B$59/12 -> 29.166667 | ... M19: =Assumptions!$B$59/12 -> 29.166667 | N19: =SUM(B19:M19) -> 350 | O19: =AVERAGE(B19:M19) -> 29.166667
A20: Total OpEx | B20: =SUM(B12:B19) -> 526.16667 | C20: =SUM(C12:C19) -> 526.16667 | D20: =SUM(D12:D19) -> 526.16667 | E20: =SUM(E12:E19) -> 526.16667 | F20: =SUM(F12:F19) -> 526.16667 | G20: =SUM(G12:G19) -> 526.16667 | H20: =SUM(H12:H19) -> 526.16667 | I20: =SUM(I12:I19) -> 526.16667 | ... M20: =SUM(M12:M19) -> 526.16667 | N20: =SUM(B20:M20) -> 6314 | O20: =AVERAGE(B20:M20) -> 526.16667
A22: NET INCOME (pre-owner pay) | B22: =B9-B20 -> 2973.8333 | C22: =C9-C20 -> 4473.8333 | D22: =D9-D20 -> 4473.8333 | E22: =E9-E20 -> 7473.8333 | F22: =F9-F20 -> 7473.8333 | G22: =G9-G20 -> 7473.8333 | H22: =H9-H20 -> 7473.8333 | I22: =I9-I20 -> 7473.8333 | ... M22: =M9-M20 -> 7473.8333 | N22: =SUM(B22:M22) -> 79186 | O22: =AVERAGE(B22:M22) -> 6598.8333
A24: Net margin % | B24: =IFERROR(B22/B9,0) -> 0.84966667 | C24: =IFERROR(C22/C9,0) -> 0.89476667 | D24: =IFERROR(D22/D9,0) -> 0.89476667 | E24: =IFERROR(E22/E9,0) -> 0.93422917 | F24: =IFERROR(F22/F9,0) -> 0.93422917 | G24: =IFERROR(G22/G9,0) -> 0.93422917 | H24: =IFERROR(H22/H9,0) -> 0.93422917 | I24: =IFERROR(I22/I9,0) -> 0.93422917 | ... N24: =IFERROR(N22/N9,0) -> 0.92615205
A26: P&L notes
A27: • Revenue mirrors the Forecast tab base scenario. Edit assumptions there to flow through.
A28: • No COGS — pure services business. Net margin equals operating margin.
A29: • Owner pay (Chance) is NOT an expense to the LLC — single-member disregarded entity flows net income to your 1040 as 1099 income, already taxed on Taxes tab.
A30: • When/if S-corp election is made, your W-2 salary from the LLC becomes an expense here, lowering LLC net income — but offset by SE tax savings on personal side. Re-model at that point.
A31: • CPA, E&O insurance, software reserve are NOT YET INCURRED — modeled as reserves to plan for. Pull from Mercury when you set them up.

Sheet Cash Roll-Forward
A1: Cash Roll-Forward (Base scenario)
A2: Starts at $11K personal cash. Sale event adds $95K. Debt payoff applied at sale month per assumptions.
A4: Line | B4: Jun-26 | C4: Jul-26 | D4: Aug-26 | E4: Sep-26 | F4: Oct-26 | G4: Nov-26 | H4: Dec-26 | I4: Jan-27 | J4: Feb-27 | K4: Mar-27 | L4: Apr-27 | M4: May-27
A5: Beginning cash | B5: =Assumptions!$B$48 -> 11000 | C5: =B12 -> 14064.029 | D5: =C12 -> 48028.057 | E5: =D12 -> 52725.086 | F5: =E12 -> 57422.114 | G5: =F12 -> 62119.143 | H5: =G12 -> 66816.171 | I5: =H12 -> 71513.2 | J5: =I12 -> 76210.228 | ... M5: =L12 -> 90301.314
A6: (+) After-tax income (Base) | B6: =Taxes!$B$43 -> 13257.195 | C6: =Taxes!$B$43 -> 13257.195 | D6: =Taxes!$B$43 -> 13257.195 | E6: =Taxes!$B$43 -> 13257.195 | F6: =Taxes!$B$43 -> 13257.195 | G6: =Taxes!$B$43 -> 13257.195 | H6: =Taxes!$B$43 -> 13257.195 | I6: =Taxes!$B$43 -> 13257.195 | ... M6: =Taxes!$B$43 -> 13257.195
A7: (−) Personal expenses | B7: =-'Personal Expenses'!B21 -> -9667 | C7: =-'Personal Expenses'!C21 -> -20267 | D7: =-'Personal Expenses'!D21 -> -8034 | E7: =-'Personal Expenses'!E21 -> -8034 | F7: =-'Personal Expenses'!F21 -> -8034 | G7: =-'Personal Expenses'!G21 -> -8034 | H7: =-'Personal Expenses'!H21 -> -8034 | I7: =-'Personal Expenses'!I21 -> -8034 | ... M7: =-'Personal Expenses'!M21 -> -8034
A8: (−) Framework OPS OpEx | B8: =-'Framework OPS P&L'!B20 -> -526.16667 | C8: =-'Framework OPS P&L'!C20 -> -526.16667 | D8: =-'Framework OPS P&L'!D20 -> -526.16667 | E8: =-'Framework OPS P&L'!E20 -> -526.16667 | F8: =-'Framework OPS P&L'!F20 -> -526.16667 | G8: =-'Framework OPS P&L'!G20 -> -526.16667 | H8: =-'Framework OPS P&L'!H20 -> -526.16667 | I8: =-'Framework OPS P&L'!I20 -> -526.16667 | ... M8: =-'Framework OPS P&L'!M20 -> -526.16667
A9: (+) Net sale proceeds | B9: =IF(1=Assumptions!$B$25,Assumptions!$B$27,0) -> 0 | C9: =IF(2=Assumptions!$B$25,Assumptions!$B$27,0) -> 95000 | D9: =IF(3=Assumptions!$B$25,Assumptions!$B$27,0) -> 0 | E9: =IF(4=Assumptions!$B$25,Assumptions!$B$27,0) -> 0 | F9: =IF(5=Assumptions!$B$25,Assumptions!$B$27,0) -> 0 | G9: =IF(6=Assumptions!$B$25,Assumptions!$B$27,0) -> 0 | H9: =IF(7=Assumptions!$B$25,Assumptions!$B$27,0) -> 0 | I9: =IF(8=Assumptions!$B$25,Assumptions!$B$27,0) -> 0 | J9: =IF(9=Assumptions!$B$25,Assumptions!$B$27,0) -> 0 | K9: =IF(10=Assumptions!$B$25,Assumptions!$B$27,0) -> 0 | L9: =IF(11=Assumptions!$B$25,Assumptions!$B$27,0) -> 0 | M9: =IF(12=Assumptions!$B$25,Assumptions!$B$27,0) -> 0
A10: (−) Debt payoff (CC, loans) | B10: =-(IF(1=Assumptions!$B$25,Assumptions!$B$35,0)+IF(AND(Assumptions!$B$37>0,1=Assumptions!$B$37),13000,0)+IF(AND(Assumptions!$B$38>0,1=Assumptions!$B$38),24500,0)) -> 0 | C10: =-(IF(2=Assumptions!$B$25,Assumptions!$B$35,0)+IF(AND(Assumptions!$B$37>0,2=Assumptions!$B$37),13000,0)+IF(AND(Assumptions!$B$38>0,2=Assumptions!$B$38),24500,0)) -> -53500 | D10: =-(IF(3=Assumptions!$B$25,Assumptions!$B$35,0)+IF(AND(Assumptions!$B$37>0,3=Assumptions!$B$37),13000,0)+IF(AND(Assumptions!$B$38>0,3=Assumptions!$B$38),24500,0)) -> 0 | E10: =-(IF(4=Assumptions!$B$25,Assumptions!$B$35,0)+IF(AND(Assumptions!$B$37>0,4=Assumptions!$B$37),13000,0)+IF(AND(Assumptions!$B$38>0,4=Assumptions!$B$38),24500,0)) -> 0 | F10: =-(IF(5=Assumptions!$B$25,Assumptions!$B$35,0)+IF(AND(Assumptions!$B$37>0,5=Assumptions!$B$37),13000,0)+IF(AND(Assumptions!$B$38>0,5=Assumptions!$B$38),24500,0)) -> 0 | G10: =-(IF(6=Assumptions!$B$25,Assumptions!$B$35,0)+IF(AND(Assumptions!$B$37>0,6=Assumptions!$B$37),13000,0)+IF(AND(Assumptions!$B$38>0,6=Assumptions!$B$38),24500,0)) -> 0 | H10: =-(IF(7=Assumptions!$B$25,Assumptions!$B$35,0)+IF(AND(Assumptions!$B$37>0,7=Assumptions!$B$37),13000,0)+IF(AND(Assumptions!$B$38>0,7=Assumptions!$B$38),24500,0)) -> 0 | I10: =-(IF(8=Assumptions!$B$25,Assumptions!$B$35,0)+IF(AND(Assumptions!$B$37>0,8=Assumptions!$B$37),13000,0)+IF(AND(Assumptions!$B$38>0,8=Assumptions!$B$38),24500,0)) -> 0 | J10: =-(IF(9=Assumptions!$B$25,Assumptions!$B$35,0)+IF(AND(Assumptions!$B$37>0,9=Assumptions!$B$37),13000,0)+IF(AND(Assumptions!$B$38>0,9=Assumptions!$B$38),24500,0)) -> 0 | K10: =-(IF(10=Assumptions!$B$25,Assumptions!$B$35,0)+IF(AND(Assumptions!$B$37>0,10=Assumptions!$B$37),13000,0)+IF(AND(Assumptions!$B$38>0,10=Assumptions!$B$38),24500,0)) -> 0 | L10: =-(IF(11=Assumptions!$B$25,Assumptions!$B$35,0)+IF(AND(Assumptions!$B$37>0,11=Assumptions!$B$37),13000,0)+IF(AND(Assumptions!$B$38>0,11=Assumptions!$B$38),24500,0)) -> 0 | M10: =-(IF(12=Assumptions!$B$25,Assumptions!$B$35,0)+IF(AND(Assumptions!$B$37>0,12=Assumptions!$B$37),13000,0)+IF(AND(Assumptions!$B$38>0,12=Assumptions!$B$38),24500,0)) -> 0
A11: Net cash change | B11: =SUM(B6:B10) -> 3064.0285 | C11: =SUM(C6:C10) -> 33964.029 | D11: =SUM(D6:D10) -> 4697.0285 | E11: =SUM(E6:E10) -> 4697.0285 | F11: =SUM(F6:F10) -> 4697.0285 | G11: =SUM(G6:G10) -> 4697.0285 | H11: =SUM(H6:H10) -> 4697.0285 | I11: =SUM(I6:I10) -> 4697.0285 | ... M11: =SUM(M6:M10) -> 4697.0285
A12: Ending cash | B12: =B5+B11 -> 14064.029 | C12: =C5+C11 -> 48028.057 | D12: =D5+D11 -> 52725.086 | E12: =E5+E11 -> 57422.114 | F12: =F5+F11 -> 62119.143 | G12: =G5+G11 -> 66816.171 | H12: =H5+H11 -> 71513.2 | I12: =I5+I11 -> 76210.228 | ... M12: =M5+M11 -> 94998.342
A14: Roll-forward notes
A15: • After-tax income line is the Base scenario monthly average from Taxes tab (B43). To stress to Downside, change formula in row 6 to Taxes!$C$43.
A16: • Framework OPS OpEx is subtracted because Carlos/Client3 receipts hit your gross 1099 income, but you actually pay these expenses from those receipts.
A17: • Sale proceeds and debt payoffs are one-time, triggered by the month set on Assumptions.
A18: • Roth IRA + 401(k) contributions are treated as outflows (they leave checking) but ARE building net worth elsewhere. Do not double-count.

Sheet Debt Strategy
A1: Debt Payoff Strategy — Recommendation
A3: Current debt stack (CC first, by APR)
A4: Debt | B4: Balance | C4: Monthly Pmt | D4: APR (est) | E4: Priority
A5: Credit cards | B5: 16000 | C5: 400 | D5: 22–29% (typ) | E5: 1 — pay off at sale (no question)
A6: Personal loan #2 | B6: 24500 | C6: 499 | D6: 12.72% | E6: 2 — pay off at sale
A7: Personal loan #1 | B7: 13000 | C7: 334 | D7: ~10.5% (calc) | E7: 3 — pay off at sale
A8: Auto loan | B8: 10000 | C8: 198 | D8: 7% | E8: 4 — KEEP (rate < safe yield)
A9: Student loan | B9: 4500 | C9: 0 | D9: n/a | E9: 0 — Skyright paying in full
A10: TOTAL | B10: =SUM(B5:B9) -> 68000 | C10: =SUM(C5:C9) -> 1431
A12: Recommended deployment of $95K sale proceeds + $11K cash
A13: Use of funds | B13: Amount | C13: Running balance
A14: Starting: existing cash + sale proceeds | B14: 106000 | C14: 106000
A15: Less: Pay off credit cards | B15: -16000 | C15: =C14+B15 -> 90000
A16: Less: Moving costs | B16: -5000 | C16: =C15+B16 -> 85000
A17: Less: Rent deposit (1st + last) | B17: -6400 | C17: =C16+B17 -> 78600
A18: Less: Pay off Personal Loan #2 ($24.5K @ 12.72%) | B18: -24500 | C18: =C17+B18 -> 54100
A19: Less: Pay off Personal Loan #1 ($13K @ ~10.5%) | B19: -13000 | C19: =C18+B19 -> 41100
A20: Remaining for emergency fund / buffer | B20: =C19 -> 41100 | C20: =C19 -> 41100
A22: Why this order (data-backed)
A23: • CCs at 22–29% APR are the most expensive debt by a wide margin. Eliminating $16K saves $3,500–$4,600/yr in interest. No-brainer.
A24: • Personal Loan #2 (12.72%) is the next-highest rate. Eliminating $24.5K saves ~$3,116/yr in interest AND frees $499/mo in cash flow.
A25: • Personal Loan #1 (~10.5% calc) is third. Eliminating $13K saves ~$1,365/yr interest, frees $334/mo cash flow.
A26: • Keep the auto loan at 7%. After-tax yield on a HYSA is currently ~4.0–4.3%; the spread isn't worth liquidating to kill a 7% debt with a low fixed payment.
A27: • Combined cash flow freed: $833/mo from killing the two personal loans. That fills the emergency fund and adds to retirement.
A28: • Total interest saved over remaining loan terms (rough): $8,000–$12,000.
A30: Risks / counterpoints (pessimistic check)
A31: • Sale price $615K is a target, not closed. If it sells for $590K, net proceeds drop to ~$72K. At that level, pay off CC + Loan #2 only; keep $11K cash + $7K residual ($18K). Loan #1 stays.
A32: • Family of 6 in housing transition + new consulting practice = volatile period. Standard advice is 6 months of essential expenses as emergency fund. Your essential burn after debt payoff is ~$7,000/mo → 6-month fund = $42K. The recommended plan leaves ~$41K — right at the floor.
A33: • CC payoff is only durable if spending behavior holds. If CCs build up again in 90 days, you've traded equity for short-term lifestyle inflation. Set up automatic full-balance pay from Mercury.
A34: • Carlos and Client 3 retainers are revocable. If both churn in Q4, you lose $6K/mo of 1099 income. The buffer covers ~6 months of that hole at current burn.
A35: • You are NOT carrying business insurance. One client lawsuit (even meritless) can wipe out the emergency fund in legal fees. E&O quote should happen this month, not next quarter.

Sheet 3-Year Growth
A1: 3-Year Growth Forecast — Framework OPS
A2: Pessimistic: ~18-mo avg client tenure | Skyright W2 ends month 13 | Retainers $1.5–4K | Solo capacity ceiling 5 active retainers post-Skyright
A4: Client / Line | B4: Jun-26 | C4: Jul-26 | D4: Aug-26 | E4: Sep-26 | F4: Oct-26 | G4: Nov-26 | H4: Dec-26 | I4: Jan-27 | J4: Feb-27 | K4: Mar-27 | L4: Apr-27 | M4: May-27 | N4: Jun-27 | O4: Jul-27 | P4: Aug-27 | Q4: Sep-27 | R4: Oct-27 | S4: Nov-27 | T4: Dec-27 | U4: Jan-28 | V4: Feb-28 | W4: Mar-28 | X4: Apr-28 | Y4: May-28 | Z4: Jun-28 | AA4: Jul-28 | AB4: Aug-28 | AC4: Sep-28 | AD4: Oct-28 | AE4: Nov-28 | AF4: Dec-28 | AG4: Jan-29 | AH4: Feb-29 | AI4: Mar-29 | AJ4: Apr-29 | AK4: May-29 | AL4: Y1 Total | AM4: Y2 Total | AN4: Y3 Total | AP4: Y-OVER-Y SUMMARY
A5: Skyright W2 | B5: 8000 | C5: 8000 | D5: 8000 | E5: 8000 | F5: 8000 | G5: 8000 | H5: 8000 | I5: 8000 | J5: 8000 | K5: 8000 | L5: 8000 | M5: 8000 | N5: 0 | O5: 0 | P5: 0 | Q5: 0 | R5: 0 | S5: 0 | T5: 0 | U5: 0 | V5: 0 | W5: 0 | X5: 0 | Y5: 0 | Z5: 0 | AA5: 0 | AB5: 0 | AC5: 0 | AD5: 0 | AE5: 0 | AF5: 0 | AG5: 0 | AH5: 0 | AI5: 0 | AJ5: 0 | AK5: 0 | AL5: =SUM(B5:M5) -> 96000 | AM5: =SUM(N5:Y5) -> 0 | AN5: =SUM(Z5:AK5) -> 0 | AP5: Metric | AQ5: Y1 | AR5: Y2 | AS5: Y3
A6: Carlos — ramp | B6: 1500 | C6: 0 | D6: 0 | E6: 0 | F6: 0 | G6: 0 | H6: 0 | I6: 0 | J6: 0 | K6: 0 | L6: 0 | M6: 0 | N6: 0 | O6: 0 | P6: 0 | Q6: 0 | R6: 0 | S6: 0 | T6: 0 | U6: 0 | V6: 0 | W6: 0 | X6: 0 | Y6: 0 | Z6: 0 | AA6: 0 | AB6: 0 | AC6: 0 | AD6: 0 | AE6: 0 | AF6: 0 | AG6: 0 | AH6: 0 | AI6: 0 | AJ6: 0 | AK6: 0 | AL6: =SUM(B6:M6) -> 1500 | AM6: =SUM(N6:Y6) -> 0 | AN6: =SUM(Z6:AK6) -> 0 | AP6: Skyright W2 | AQ6: =AL5 -> 96000 | AR6: =AM5 -> 0 | AS6: =AN5 -> 0
A7: Carlos — full | B7: 0 | C7: 3000 | D7: 3000 | E7: 3000 | F7: 3000 | G7: 3000 | H7: 3000 | I7: 3000 | J7: 3000 | K7: 3000 | L7: 3000 | M7: 3000 | N7: 3000 | O7: 3000 | P7: 3000 | Q7: 3000 | R7: 3000 | S7: 3000 | T7: 3000 | U7: 3000 | V7: 3000 | W7: 0 | X7: 0 | Y7: 0 | Z7: 0 | AA7: 0 | AB7: 0 | AC7: 0 | AD7: 0 | AE7: 0 | AF7: 0 | AG7: 0 | AH7: 0 | AI7: 0 | AJ7: 0 | AK7: 0 | AL7: =SUM(B7:M7) -> 33000 | AM7: =SUM(N7:Y7) -> 27000 | AN7: =SUM(Z7:AK7) -> 0 | AP7: Framework OPS revenue | AQ7: =AL18-AL5 -> 98000 | AR7: =AM18-AM5 -> 169000 | AS7: =AN18-AN5 -> 195000
A8: Client 3 (assumed) | B8: 0 | C8: 0 | D8: 0 | E8: 3000 | F8: 3000 | G8: 3000 | H8: 3000 | I8: 3000 | J8: 3000 | K8: 3000 | L8: 3000 | M8: 3000 | N8: 3000 | O8: 3000 | P8: 3000 | Q8: 3000 | R8: 3000 | S8: 3000 | T8: 3000 | U8: 0 | V8: 0 | W8: 0 | X8: 0 | Y8: 0 | Z8: 0 | AA8: 0 | AB8: 0 | AC8: 0 | AD8: 0 | AE8: 0 | AF8: 0 | AG8: 0 | AH8: 0 | AI8: 0 | AJ8: 0 | AK8: 0 | AL8: =SUM(B8:M8) -> 27000 | AM8: =SUM(N8:Y8) -> 21000 | AN8: =SUM(Z8:AK8) -> 0 | AP8: Total gross income | AQ8: =AL18 -> 194000 | AR8: =AM18 -> 169000 | AS8: =AN18 -> 195000
A9: Daniel + Upwork | B9: 2000 | C9: 2000 | D9: 2000 | E9: 2000 | F9: 2000 | G9: 2000 | H9: 2000 | I9: 2000 | J9: 2000 | K9: 2000 | L9: 2000 | M9: 2000 | N9: 2000 | O9: 2000 | P9: 2000 | Q9: 2000 | R9: 2000 | S9: 2000 | T9: 2000 | U9: 2000 | V9: 2000 | W9: 2000 | X9: 2000 | Y9: 2000 | Z9: 2000 | AA9: 2000 | AB9: 2000 | AC9: 2000 | AD9: 2000 | AE9: 2000 | AF9: 0 | AG9: 0 | AH9: 0 | AI9: 0 | AJ9: 0 | AK9: 0 | AL9: =SUM(B9:M9) -> 24000 | AM9: =SUM(N9:Y9) -> 24000 | AN9: =SUM(Z9:AK9) -> 12000 | AP9: OpEx | AQ9: =AL23 -> -6312 | AR9: =AM23 -> -9000 | AS9: =AN23 -> -13200
A10: New Retainer #1 | B10: 0 | C10: 0 | D10: 0 | E10: 0 | F10: 0 | G10: 0 | H10: 0 | I10: 2500 | J10: 2500 | K10: 2500 | L10: 2500 | M10: 2500 | N10: 2500 | O10: 2500 | P10: 2500 | Q10: 2500 | R10: 2500 | S10: 2500 | T10: 2500 | U10: 2500 | V10: 2500 | W10: 2500 | X10: 2500 | Y10: 2500 | Z10: 2500 | AA10: 0 | AB10: 0 | AC10: 0 | AD10: 0 | AE10: 0 | AF10: 0 | AG10: 0 | AH10: 0 | AI10: 0 | AJ10: 0 | AK10: 0 | AL10: =SUM(B10:M10) -> 12500 | AM10: =SUM(N10:Y10) -> 30000 | AN10: =SUM(Z10:AK10) -> 2500 | AP10: Net income (pre-owner) | AQ10: =AL24 -> 187688 | AR10: =AM24 -> 160000 | AS10: =AN24 -> 181800
A11: New Retainer #2 | B11: 0 | C11: 0 | D11: 0 | E11: 0 | F11: 0 | G11: 0 | H11: 0 | I11: 0 | J11: 0 | K11: 0 | L11: 0 | M11: 0 | N11: 0 | O11: 3000 | P11: 3000 | Q11: 3000 | R11: 3000 | S11: 3000 | T11: 3000 | U11: 3000 | V11: 3000 | W11: 3000 | X11: 3000 | Y11: 3000 | Z11: 3000 | AA11: 3000 | AB11: 3000 | AC11: 3000 | AD11: 3000 | AE11: 3000 | AF11: 3000 | AG11: 0 | AH11: 0 | AI11: 0 | AJ11: 0 | AK11: 0 | AL11: =SUM(B11:M11) -> 0 | AM11: =SUM(N11:Y11) -> 33000 | AN11: =SUM(Z11:AK11) -> 21000 | AP11: YoY growth % | AQ11: — | AR11: =AM24/AL24-1 -> -0.14752142 | AS11: =AN24/AM24-1 -> 0.13625
A12: New Retainer #3 | B12: 0 | C12: 0 | D12: 0 | E12: 0 | F12: 0 | G12: 0 | H12: 0 | I12: 0 | J12: 0 | K12: 0 | L12: 0 | M12: 0 | N12: 0 | O12: 0 | P12: 0 | Q12: 0 | R12: 0 | S12: 3000 | T12: 3000 | U12: 3000 | V12: 3000 | W12: 3000 | X12: 3000 | Y12: 3000 | Z12: 3000 | AA12: 3000 | AB12: 3000 | AC12: 3000 | AD12: 3000 | AE12: 3000 | AF12: 3000 | AG12: 3000 | AH12: 3000 | AI12: 3000 | AJ12: 3000 | AK12: 3000 | AL12: =SUM(B12:M12) -> 0 | AM12: =SUM(N12:Y12) -> 21000 | AN12: =SUM(Z12:AK12) -> 36000 | AP12: End-Y active retainers | AQ12: =M20 -> 3 | AR12: =Y20 -> 5 | AS12: =AK20 -> 5
A13: New Retainer #4 | B13: 0 | C13: 0 | D13: 0 | E13: 0 | F13: 0 | G13: 0 | H13: 0 | I13: 0 | J13: 0 | K13: 0 | L13: 0 | M13: 0 | N13: 0 | O13: 0 | P13: 0 | Q13: 0 | R13: 0 | S13: 0 | T13: 0 | U13: 0 | V13: 0 | W13: 3500 | X13: 3500 | Y13: 3500 | Z13: 3500 | AA13: 3500 | AB13: 3500 | AC13: 3500 | AD13: 3500 | AE13: 3500 | AF13: 3500 | AG13: 3500 | AH13: 3500 | AI13: 3500 | AJ13: 3500 | AK13: 3500 | AL13: =SUM(B13:M13) -> 0 | AM13: =SUM(N13:Y13) -> 10500 | AN13: =SUM(Z13:AK13) -> 42000 | AP13: Avg retainer count | AQ13: =AVERAGE(B20:M20) -> 2.0833333 | AR13: =AVERAGE(N20:Y20) -> 4.1666667 | AS13: =AVERAGE(Z20:AK20) -> 4.8333333
A14: Replacement A | B14: 0 | C14: 0 | D14: 0 | E14: 0 | F14: 0 | G14: 0 | H14: 0 | I14: 0 | J14: 0 | K14: 0 | L14: 0 | M14: 0 | N14: 0 | O14: 0 | P14: 0 | Q14: 0 | R14: 0 | S14: 0 | T14: 0 | U14: 0 | V14: 0 | W14: 0 | X14: 0 | Y14: 2500 | Z14: 2500 | AA14: 2500 | AB14: 2500 | AC14: 2500 | AD14: 2500 | AE14: 2500 | AF14: 2500 | AG14: 2500 | AH14: 2500 | AI14: 2500 | AJ14: 2500 | AK14: 2500 | AL14: =SUM(B14:M14) -> 0 | AM14: =SUM(N14:Y14) -> 2500 | AN14: =SUM(Z14:AK14) -> 30000
A15: New Retainer #5 | B15: 0 | C15: 0 | D15: 0 | E15: 0 | F15: 0 | G15: 0 | H15: 0 | I15: 0 | J15: 0 | K15: 0 | L15: 0 | M15: 0 | N15: 0 | O15: 0 | P15: 0 | Q15: 0 | R15: 0 | S15: 0 | T15: 0 | U15: 0 | V15: 0 | W15: 0 | X15: 0 | Y15: 0 | Z15: 0 | AA15: 0 | AB15: 0 | AC15: 3500 | AD15: 3500 | AE15: 3500 | AF15: 3500 | AG15: 3500 | AH15: 3500 | AI15: 3500 | AJ15: 3500 | AK15: 3500 | AL15: =SUM(B15:M15) -> 0 | AM15: =SUM(N15:Y15) -> 0 | AN15: =SUM(Z15:AK15) -> 31500
A16: New Retainer #6 | B16: 0 | C16: 0 | D16: 0 | E16: 0 | F16: 0 | G16: 0 | H16: 0 | I16: 0 | J16: 0 | K16: 0 | L16: 0 | M16: 0 | N16: 0 | O16: 0 | P16: 0 | Q16: 0 | R16: 0 | S16: 0 | T16: 0 | U16: 0 | V16: 0 | W16: 0 | X16: 0 | Y16: 0 | Z16: 0 | AA16: 0 | AB16: 0 | AC16: 0 | AD16: 0 | AE16: 0 | AF16: 0 | AG16: 4000 | AH16: 4000 | AI16: 4000 | AJ16: 4000 | AK16: 4000 | AL16: =SUM(B16:M16) -> 0 | AM16: =SUM(N16:Y16) -> 0 | AN16: =SUM(Z16:AK16) -> 20000
A18: TOTAL REVENUE | B18: =SUM(B5:B16) -> 11500 | C18: =SUM(C5:C16) -> 13000 | D18: =SUM(D5:D16) -> 13000 | E18: =SUM(E5:E16) -> 16000 | F18: =SUM(F5:F16) -> 16000 | G18: =SUM(G5:G16) -> 16000 | H18: =SUM(H5:H16) -> 16000 | I18: =SUM(I5:I16) -> 18500 | ... AK18: =SUM(AK5:AK16) -> 16500 | AL18: =SUM(B18:M18) -> 194000 | AM18: =SUM(N18:Y18) -> 169000 | AN18: =SUM(Z18:AK18) -> 195000
A20: Active retainers count | B20: =IF(B7>0,1,0)+IF(B8>0,1,0)+IF(B10>0,1,0)+IF(B11>0,1,0)+IF(B12>0,1,0)+IF(B13>0,1,0)+IF(B14>0,1,0)+IF(B15>0,1,0)+IF(B16>0,1,0) -> 0 | C20: =IF(C7>0,1,0)+IF(C8>0,1,0)+IF(C10>0,1,0)+IF(C11>0,1,0)+IF(C12>0,1,0)+IF(C13>0,1,0)+IF(C14>0,1,0)+IF(C15>0,1,0)+IF(C16>0,1,0) -> 1 | D20: =IF(D7>0,1,0)+IF(D8>0,1,0)+IF(D10>0,1,0)+IF(D11>0,1,0)+IF(D12>0,1,0)+IF(D13>0,1,0)+IF(D14>0,1,0)+IF(D15>0,1,0)+IF(D16>0,1,0) -> 1 | E20: =IF(E7>0,1,0)+IF(E8>0,1,0)+IF(E10>0,1,0)+IF(E11>0,1,0)+IF(E12>0,1,0)+IF(E13>0,1,0)+IF(E14>0,1,0)+IF(E15>0,1,0)+IF(E16>0,1,0) -> 2 | F20: =IF(F7>0,1,0)+IF(F8>0,1,0)+IF(F10>0,1,0)+IF(F11>0,1,0)+IF(F12>0,1,0)+IF(F13>0,1,0)+IF(F14>0,1,0)+IF(F15>0,1,0)+IF(F16>0,1,0) -> 2 | G20: =IF(G7>0,1,0)+IF(G8>0,1,0)+IF(G10>0,1,0)+IF(G11>0,1,0)+IF(G12>0,1,0)+IF(G13>0,1,0)+IF(G14>0,1,0)+IF(G15>0,1,0)+IF(G16>0,1,0) -> 2 | H20: =IF(H7>0,1,0)+IF(H8>0,1,0)+IF(H10>0,1,0)+IF(H11>0,1,0)+IF(H12>0,1,0)+IF(H13>0,1,0)+IF(H14>0,1,0)+IF(H15>0,1,0)+IF(H16>0,1,0) -> 2 | I20: =IF(I7>0,1,0)+IF(I8>0,1,0)+IF(I10>0,1,0)+IF(I11>0,1,0)+IF(I12>0,1,0)+IF(I13>0,1,0)+IF(I14>0,1,0)+IF(I15>0,1,0)+IF(I16>0,1,0) -> 3 | ... AK20: =IF(AK7>0,1,0)+IF(AK8>0,1,0)+IF(AK10>0,1,0)+IF(AK11>0,1,0)+IF(AK12>0,1,0)+IF(AK13>0,1,0)+IF(AK14>0,1,0)+IF(AK15>0,1,0)+IF(AK16>0,1,0) -> 5
A21: Capacity flag (3 w/Skyright, 5 after) | B21: =IF(1<=12,IF(B20>3,"OVER",""),IF(B20>5,"OVER","")) | C21: =IF(2<=12,IF(C20>3,"OVER",""),IF(C20>5,"OVER","")) | D21: =IF(3<=12,IF(D20>3,"OVER",""),IF(D20>5,"OVER","")) | E21: =IF(4<=12,IF(E20>3,"OVER",""),IF(E20>5,"OVER","")) | F21: =IF(5<=12,IF(F20>3,"OVER",""),IF(F20>5,"OVER","")) | G21: =IF(6<=12,IF(G20>3,"OVER",""),IF(G20>5,"OVER","")) | H21: =IF(7<=12,IF(H20>3,"OVER",""),IF(H20>5,"OVER","")) | I21: =IF(8<=12,IF(I20>3,"OVER",""),IF(I20>5,"OVER","")) | J21: =IF(9<=12,IF(J20>3,"OVER",""),IF(J20>5,"OVER","")) | K21: =IF(10<=12,IF(K20>3,"OVER",""),IF(K20>5,"OVER","")) | L21: =IF(11<=12,IF(L20>3,"OVER",""),IF(L20>5,"OVER","")) | M21: =IF(12<=12,IF(M20>3,"OVER",""),IF(M20>5,"OVER","")) | N21: =IF(13<=12,IF(N20>3,"OVER",""),IF(N20>5,"OVER","")) | O21: =IF(14<=12,IF(O20>3,"OVER",""),IF(O20>5,"OVER","")) | P21: =IF(15<=12,IF(P20>3,"OVER",""),IF(P20>5,"OVER","")) | Q21: =IF(16<=12,IF(Q20>3,"OVER",""),IF(Q20>5,"OVER","")) | R21: =IF(17<=12,IF(R20>3,"OVER",""),IF(R20>5,"OVER","")) | S21: =IF(18<=12,IF(S20>3,"OVER",""),IF(S20>5,"OVER","")) | T21: =IF(19<=12,IF(T20>3,"OVER",""),IF(T20>5,"OVER","")) | U21: =IF(20<=12,IF(U20>3,"OVER",""),IF(U20>5,"OVER","")) | V21: =IF(21<=12,IF(V20>3,"OVER",""),IF(V20>5,"OVER","")) | W21: =IF(22<=12,IF(W20>3,"OVER",""),IF(W20>5,"OVER","")) | X21: =IF(23<=12,IF(X20>3,"OVER",""),IF(X20>5,"OVER","")) | Y21: =IF(24<=12,IF(Y20>3,"OVER",""),IF(Y20>5,"OVER","")) | Z21: =IF(25<=12,IF(Z20>3,"OVER",""),IF(Z20>5,"OVER","")) | AA21: =IF(26<=12,IF(AA20>3,"OVER",""),IF(AA20>5,"OVER","")) | AB21: =IF(27<=12,IF(AB20>3,"OVER",""),IF(AB20>5,"OVER","")) | AC21: =IF(28<=12,IF(AC20>3,"OVER",""),IF(AC20>5,"OVER","")) | AD21: =IF(29<=12,IF(AD20>3,"OVER",""),IF(AD20>5,"OVER","")) | AE21: =IF(30<=12,IF(AE20>3,"OVER",""),IF(AE20>5,"OVER","")) | AF21: =IF(31<=12,IF(AF20>3,"OVER",""),IF(AF20>5,"OVER","")) | AG21: =IF(32<=12,IF(AG20>3,"OVER",""),IF(AG20>5,"OVER","")) | AH21: =IF(33<=12,IF(AH20>3,"OVER",""),IF(AH20>5,"OVER","")) | AI21: =IF(34<=12,IF(AI20>3,"OVER",""),IF(AI20>5,"OVER","")) | AJ21: =IF(35<=12,IF(AJ20>3,"OVER",""),IF(AJ20>5,"OVER","")) | AK21: =IF(36<=12,IF(AK20>3,"OVER",""),IF(AK20>5,"OVER",""))
A23: Less: Framework OPS OpEx (scales) | B23: -526 | C23: -526 | D23: -526 | E23: -526 | F23: -526 | G23: -526 | H23: -526 | I23: -526 | J23: -526 | K23: -526 | L23: -526 | M23: -526 | N23: -750 | O23: -750 | P23: -750 | Q23: -750 | R23: -750 | S23: -750 | T23: -750 | U23: -750 | V23: -750 | W23: -750 | X23: -750 | Y23: -750 | Z23: -1100 | AA23: -1100 | AB23: -1100 | AC23: -1100 | AD23: -1100 | AE23: -1100 | AF23: -1100 | AG23: -1100 | AH23: -1100 | AI23: -1100 | AJ23: -1100 | AK23: -1100 | AL23: =SUM(B23:M23) -> -6312 | AM23: =SUM(N23:Y23) -> -9000 | AN23: =SUM(Z23:AK23) -> -13200
A24: NET PRE-OWNER PAY | B24: =B18+B23 -> 10974 | C24: =C18+C23 -> 12474 | D24: =D18+D23 -> 12474 | E24: =E18+E23 -> 15474 | F24: =F18+F23 -> 15474 | G24: =G18+G23 -> 15474 | H24: =H18+H23 -> 15474 | I24: =I18+I23 -> 17974 | ... AN24: =AN18+AN23 -> 181800
A27: PESSIMISTIC ASSUMPTIONS BAKED IN
A28: • Each client: start month and churn month (first inactive month). Avg tenure 16-20 mo, just above industry 30%+ annual churn worst case.
A29: • Y1 cap with Skyright: 3 active retainers. Roster respects this — Carlos + Client 3 + New #1 = 3 by Jan-27.
A30: • Y2/Y3 cap post-Skyright: 5 active retainers + variable. Solo capacity ceiling.
A31: • Acquisition pace: 1 every ~3-4 mo while at Skyright, then 1 every ~2 mo full-time. Pessimistic — accounts for 2-4 week sales cycle and ~30% close rate.
A32: • Replacement A explicitly modeled to replace Carlos churn at mo 24.
A33: • Avg retainer matures: $2,500-$3,000 early → $3,500-$4,000 by Y3 as pricing power grows.
A34: • OpEx scales: $526/mo Y1 → $750/mo Y2 (CPA active, E&O insurance) → $1,100/mo Y3 (virtual EA, expanded tools).
A35: • Daniel/Upwork variable modeled through mo 30, then churns. No replacement variable income.
A36: • Capacity flag flips to "OVER" if active retainer count exceeds period ceiling — sanity check.
A37: • This is NET pre-owner-pay (LLC level). Owner take-home flows to personal side and is taxed there.
A40: STRESS-TEST WARNINGS
... A48: • Solo 401(k) on $1099 income should be in place by Y2 — biggest tax lever, not yet modeled in the 3-yr view.
